Workbook
Name AREAland.C: [1]input!$L$287
Name AREAland.R: [1]input!$L$259
Name AREAsea.C: [1]input!$L$288
Name AREAsea.R: [1]input!$L$260
Name DEPTHfreshwater.C: [1]input!$L$300
Name DEPTHfreshwater.R: [1]input!$L$270
Name DEPTHlake.C: [1]input!$L$299
Name DEPTHlake.R: [1]input!$L$269
Name FRACagsoil.C: [1]input!$L$294
Name FRACfresh.C: [1]input!$L$292
Name FRAClake.C: [1]input!$L$291
Name FRACnatsoil.C: [1]input!$L$293
Name FRACothersoil.C: [1]input!$L$295
Name période_sélectionnée: [2]Echéancier!$H$2
Name PériodeDansPlan: [2]Echéancier!A$5=MEDIAN([2]Echéancier!A$5,[2]Echéancier!$C1,[2]Echéancier!$C1+[2]Echéancier!$D1-1)
Name PériodeDansRéel: [2]Echéancier!A$5=MEDIAN([2]Echéancier!A$5,[2]Echéancier!$E1,[2]Echéancier!$E1+[2]Echéancier!$F1-1)
Name Plan: PériodeDansPlan*([2]Echéancier!$C1>0)
Name PourcentageAccompli: PourcentageAccompliAuDelà*PériodeDansPlan
Name Réel: (PériodeDansRéel*([2]Echéancier!$E1>0))*PériodeDansPlan
Name RéelAuDelà: PériodeDansRéel*([2]Echéancier!$E1>0)
Name RegionBaseRowNr: [3]Run!$F$10
Name SYSTEMAREA.C: [1]continental!$L$16
Name SYSTEMAREA.R: [1]regional!$L$16

Sheet description
B3: SUPPORTING INFORMATION FOR:
B5: Louvet, J., Quik, J.T.K., Boulay A.-M. (under review). Regionalized Characterization Factors for Microplastics Emissions in Life Cycle Assessment Considering Multimedia Fate Modelling
B9: Description:
B10: Supplementary information with derivation of input data for SimpleBox object-oriented (SBoo): degradation data, landscape data, UV intensity calculations, exposure and effect factors (EEFs), SDFs.
B14: Table of content:
B16: 1.1 Fate Factors calculated (in days)
B17: 2.1 SSDRs for water compartments
B18: 2.2 SSDRs for sediment compartments
B19: 2.3 SSDRs for soil compartments
B20: 3.1 Default sedimentation rates for low-density polymers
B21: 4.1. Regionalization parameters
B22: 4.2. Calculations of regionalized depth and surface area for lake and river
B23: 5. References

Sheet 1.1.SSDR_water
B2: SSDR water
B4: SSDR values are taken from Louvet et al. (2026), Saadi et al. (2025), Saadi & Boulay (2026), and Corella-Puertas et al. (2023). SBoo requires [m/s] as an input for Kssdr. It is assumed that SSDRs are log-normally distributed (Corella-Puertas et al., 2023), and that the lower to upper limit represents the 99% confidence interval (CI), from which the distribution parameters are derived and used as an input in SBoo (for probabilistic solver). However, when plasticFADE model empirical degradation constants (and their CI) are available, they are used as input to compute degradation rates, ignoring the values below.
I5: log-normal distribution | J5: z_0.995 = | K5: 2.576
B6: Polymer type | C6: Geometric mean SSDR [µm/year] | D6: Lower limit SSDR [µm/year] | E6: Upper limit SSDR [µm/year] | F6: Geometric mean SSDR [m/s] | G6: Lower limit SSDR [m/s] | H6: Upper limit SSDR [m/s] | I6: mu | J6: sigma
B7: EPS | C7: =GEOMEAN(D7,E7) -> 0.031622777 | D7: 0.001 | E7: 1 | F7: =GEOMEAN(G7:H7) -> 1.0027517e-15 | G7: =(D7*0.000001)/(365*24*3600) -> 3.1709792e-17 | H7: =(E7*0.000001)/(365*24*3600) -> 3.1709792e-14 | I7: =LN(F7) -> -34.536029 | J7: =(LN(H7)-LN(G7))/(2*$K$5) -> 1.340791
B8: HDPE | C8: =GEOMEAN(D8,E8) -> 0.10954451 | D8: 0.001 | E8: 12 | F8: =GEOMEAN(G8:H8) -> 3.4736337e-15 | G8: =(D8*0.000001)/(365*24*3600) -> 3.1709792e-17 | H8: =(E8*0.000001)/(365*24*3600) -> 3.805175e-13 | I8: =LN(F8) -> -33.293575 | J8: =(LN(H8)-LN(G8))/(2*$K$5) -> 1.8231098
B9: LDPE | C9: =GEOMEAN(D9,E9) -> 0.19498718 | D9: 0.001 | E9: 38.02 | F9: =GEOMEAN(G9:H9) -> 6.1830029e-15 | G9: =(D9*0.000001)/(365*24*3600) -> 3.1709792e-17 | H9: =(E9*0.000001)/(365*24*3600) -> 1.2056063e-12 | I9: =LN(F9) -> -32.716972 | J9: =(LN(H9)-LN(G9))/(2*$K$5) -> 2.0469464
B10: PA_Nylon | C10: =GEOMEAN(D10,E10) -> 3.2 | D10: 0.032 | E10: 320 | F10: =GEOMEAN(G10:H10) -> 1.0147133e-13 | G10: =(D10*0.000001)/(365*24*3600) -> 1.0147133e-15 | H10: =(E10*0.000001)/(365*24*3600) -> 1.0147133e-11 | I10: =LN(F10) -> -29.919 | J10: =(LN(H10)-LN(G10))/(2*$K$5) -> 1.7877213
B11: PET | C11: =GEOMEAN(D11,E11) -> 0.32403703 | D11: 0.001 | E11: 105 | F11: =GEOMEAN(G11:H11) -> 1.0275147e-14 | G11: =(D11*0.000001)/(365*24*3600) -> 3.1709792e-17 | H11: =(E11*0.000001)/(365*24*3600) -> 3.3295282e-12 | I11: =LN(F11) -> -32.209048 | J11: =(LN(H11)-LN(G11))/(2*$K$5) -> 2.2441218
B12: PP | C12: =GEOMEAN(D12,E12) -> 1.2328828 | D12: 0.2 | E12: 7.6 | F12: =GEOMEAN(G12:H12) -> 3.9094457e-14 | G12: =(D12*0.000001)/(365*24*3600) -> 6.3419584e-15 | H12: =(E12*0.000001)/(365*24*3600) -> 2.4099442e-13 | I12: =LN(F12) -> -30.872796 | J12: =(LN(H12)-LN(G12))/(2*$K$5) -> 0.70605321
B13: PS | C13: =GEOMEAN(D13,E13) -> 0.031622777 | D13: 0.001 | E13: 1 | F13: =GEOMEAN(G13:H13) -> 1.0027517e-15 | G13: =(D13*0.000001)/(365*24*3600) -> 3.1709792e-17 | H13: =(E13*0.000001)/(365*24*3600) -> 3.1709792e-14 | I13: =LN(F13) -> -34.536029 | J13: =(LN(H13)-LN(G13))/(2*$K$5) -> 1.340791
B14: PVC | C14: =GEOMEAN(D14,E14) -> 0.01 | D14: 0.001 | E14: 0.1 | F14: =GEOMEAN(G14:H14) -> 3.1709792e-16 | G14: =(D14*0.000001)/(365*24*3600) -> 3.1709792e-17 | H14: =(E14*0.000001)/(365*24*3600) -> 3.1709792e-15 | I14: =LN(F14) -> -35.687321 | J14: =(LN(H14)-LN(G14))/(2*$K$5) -> 0.89386067
B15: PU | C15: =GEOMEAN(D15,E15) -> 0.25248762 | D15: 0.001 | E15: 63.75 | F15: =GEOMEAN(G15:H15) -> 8.00633e-15 | G15: =(D15*0.000001)/(365*24*3600) -> 3.1709792e-17 | H15: =(E15*0.000001)/(365*24*3600) -> 2.0214992e-12 | I15: =LN(F15) -> -32.458544 | J15: =(LN(H15)-LN(G15))/(2*$K$5) -> 2.1472679
B16: PAN | C16: =GEOMEAN(D16,E16) -> 0.01 | D16: 0.001 | E16: 0.1 | F16: =GEOMEAN(G16:H16) -> 3.1709792e-16 | G16: =(D16*0.000001)/(365*24*3600) -> 3.1709792e-17 | H16: =(E16*0.000001)/(365*24*3600) -> 3.1709792e-15 | I16: =LN(F16) -> -35.687321 | J16: =(LN(H16)-LN(G16))/(2*$K$5) -> 0.89386067
B17: TRWP | C17: - | D17: - | E17: - | F17: =GEOMEAN(G17:H17) -> 3.3287916e-15 | G17: 3.16881e-17 | H17: 3.49685e-13 | I17: =LN(F17) -> -33.336167 | J17: =(LN(H17)-LN(G17))/(2*$K$5) -> 1.8068414
B18: PHA | C18: =GEOMEAN(D18,E18) -> 112.62327 | D18: 7.55 | E18: 1680 | F18: =GEOMEAN(G18:H18) -> 3.5712603e-12 | G18: =(D18*0.000001)/(365*24*3600) -> 2.3940893e-13 | H18: =(E18*0.000001)/(365*24*3600) -> 5.3272451e-11 | I18: =LN(F18) -> -26.358103 | J18: =(LN(H18)-LN(G18))/(2*$K$5) -> 1.0491074
B19: PLA | C19: =GEOMEAN(D19,E19) -> 0.08660254 | D19: 0.001 | E19: 7.5 | F19: =GEOMEAN(G19:H19) -> 2.7461485e-15 | G19: =(D19*0.000001)/(365*24*3600) -> 3.1709792e-17 | H19: =(E19*0.000001)/(365*24*3600) -> 2.3782344e-13 | I19: =LN(F19) -> -33.528577 | J19: =(LN(H19)-LN(G19))/(2*$K$5) -> 1.7318824
B20: PCL | C20: =GEOMEAN(D20,E20) -> 14.839903 | D20: 1.31416 | E20: 167.5768 | F20: =GEOMEAN(G20:H20) -> 4.7057024e-13 | G20: =(D20*0.000001)/(365*24*3600) -> 4.167174e-14 | H20: =(E20*0.000001)/(365*24*3600) -> 5.3138255e-12 | I20: =LN(F20) -> -28.384831 | J20: =(LN(H20)-LN(G20))/(2*$K$5) -> 0.94104116
B21: PBSA | C21: =GEOMEAN(D21,E21) -> 1.5655184 | D21: 0.608 | E21: 4.031 | F21: =GEOMEAN(G21:H21) -> 4.9642264e-14 | G21: =(D21*0.000001)/(365*24*3600) -> 1.9279554e-14 | H21: =(E21*0.000001)/(365*24*3600) -> 1.2782217e-13 | I21: =LN(F21) -> -30.633934 | J21: =(LN(H21)-LN(G21))/(2*$K$5) -> 0.36715739
B22: starch_blend | C22: 101.29 | D22: =C22/10 -> 10.129 | E22: =C22*10 -> 1012.9 | F22: =GEOMEAN(G22:H22) -> 3.2118848e-12 | G22: =(D22*0.000001)/(365*24*3600) -> 3.2118848e-13 | H22: =(E22*0.000001)/(365*24*3600) -> 3.2118848e-11 | I22: =LN(F22) -> -26.464163 | J22: =(LN(H22)-LN(G22))/(2*$K$5) -> 0.89386067
B23: PBAT | C23: =GEOMEAN(D23,E23) -> 11.752936 | D23: 10.27 | E23: 13.45 | F23: =GEOMEAN(G23:H23) -> 3.7268315e-13 | G23: =(D23*0.000001)/(365*24*3600) -> 3.2565956e-13 | H23: =(E23*0.000001)/(365*24*3600) -> 4.264967e-13 | I23: =LN(F23) -> -28.618048 | J23: =(LN(H23)-LN(G23))/(2*$K$5) -> 0.052358712
B24: Cotton | C24: =GEOMEAN(D24,E24) -> 18.300786 | D24: 5.9971847 | E24: 55.845997 | F24: =GEOMEAN(G24:H24) -> 5.8031411e-13 | G24: =(D24*0.000001)/(365*24*3600) -> 1.9016948e-13 | H24: =(E24*0.000001)/(365*24*3600) -> 1.770865e-12 | I24: =LN(F24) -> -28.175207 | J24: =(LN(H24)-LN(G24))/(2*$K$5) -> 0.43309544
B25: Linen | C25: =GEOMEAN(D25,E25) -> 32.689902 | D25: 21.74 | E25: 49.155 | F25: =GEOMEAN(G25:H25) -> 1.03659e-12 | G25: =(D25*0.000001)/(365*24*3600) -> 6.8937088e-13 | H25: =(E25*0.000001)/(365*24*3600) -> 1.5586948e-12 | I25: =LN(F25) -> -27.595085 | J25: =(LN(H25)-LN(G25))/(2*$K$5) -> 0.15835107
B26: Viscose | C26: =GEOMEAN(D26,E26) -> 24.559331 | D26: 21.922321 | E26: 27.513544 | F26: =GEOMEAN(G26:H26) -> 7.7877128e-13 | G26: =(D26*0.000001)/(365*24*3600) -> 6.9515223e-13 | H26: =(E26*0.000001)/(365*24*3600) -> 8.7244877e-13 | I26: =LN(F26) -> -27.881059 | J26: =(LN(H26)-LN(G26))/(2*$K$5) -> 0.044094154
B27: Rayon | C27: =GEOMEAN(D27,E27) -> 24.559331 | D27: 21.922321 | E27: 27.513544 | F27: =GEOMEAN(G27:H27) -> 7.7877128e-13 | G27: =(D27*0.000001)/(365*24*3600) -> 6.9515223e-13 | H27: =(E27*0.000001)/(365*24*3600) -> 8.7244877e-13 | I27: =LN(F27) -> -27.881059 | J27: =(LN(H27)-LN(G27))/(2*$K$5) -> 0.044094154
B28: Lyocell | C28: =GEOMEAN(D28,E28) -> 39.899771 | D28: 37.799367 | E28: 42.116889 | F28: =GEOMEAN(G28:H28) -> 1.2652134e-12 | G28: =(D28*0.000001)/(365*24*3600) -> 1.1986101e-12 | H28: =(E28*0.000001)/(365*24*3600) -> 1.3355178e-12 | I28: =LN(F28) -> -27.39578 | J28: =(LN(H28)-LN(G28))/(2*$K$5) -> 0.020993104
B29: Modal | C29: =GEOMEAN(D29,E29) -> 51.909814 | D29: 49.834159 | E29: 54.071923 | F29: =GEOMEAN(G29:H29) -> 1.6460494e-12 | G29: =(D29*0.000001)/(365*24*3600) -> 1.5802308e-12 | H29: =(E29*0.000001)/(365*24*3600) -> 1.7146094e-12 | I29: =LN(F29) -> -27.132643 | J29: =(LN(H29)-LN(G29))/(2*$K$5) -> 0.015841305

Sheet 1.2.SSDR_sediment
B2: SSDR sediment
B4: SSDR values are taken from Louvet et al. (2026), Saadi et al. (2025), Saadi & Boulay (2026), and Corella-Puertas et al. (2023). SBoo requires [m/s] as an input for Kssdr. It is assumed that SSDRs are log-normally distributed (Corella-Puertas et al., 2023), and that the lower to upper limit represents the 99% confidence interval (CI), from which the distribution parameters are derived and used as an input in SBoo (for probabilistic solver). However, when plasticFADE model empirical degradation constants (and their CI) are available, they are used as input to compute degradation rates, ignoring the values below.
I5: log-normal distribution | J5: z_0.995 = | K5: 2.576
B6: Polymer type | C6: Geometric mean SSDR [µm/year] | D6: Lower limit SSDR [µm/year] | E6: Upper limit SSDR [µm/year] | F6: Geometric mean SSDR [m/s] | G6: Lower limit SSDR [m/s] | H6: Upper limit SSDR [m/s] | I6: mu | J6: sigma
B7: EPS | C7: =GEOMEAN(D7,E7) -> 0.031622777 | D7: 0.001 | E7: 1 | F7: =GEOMEAN(G7:H7) -> 1.0027517e-15 | G7: =(D7*0.000001)/(365*24*3600) -> 3.1709792e-17 | H7: =(E7*0.000001)/(365*24*3600) -> 3.1709792e-14 | I7: =LN(F7) -> -34.536029 | J7: =(LN(H7)-LN(G7))/(2*$K$5) -> 1.340791
B8: HDPE | C8: =GEOMEAN(D8,E8) -> 0.10954451 | D8: 0.001 | E8: 12 | F8: =GEOMEAN(G8:H8) -> 3.4736337e-15 | G8: =(D8*0.000001)/(365*24*3600) -> 3.1709792e-17 | H8: =(E8*0.000001)/(365*24*3600) -> 3.805175e-13 | I8: =LN(F8) -> -33.293575 | J8: =(LN(H8)-LN(G8))/(2*$K$5) -> 1.8231098
B9: LDPE | C9: =GEOMEAN(D9,E9) -> 0.70413067 | D9: 0.67 | E9: 0.74 | F9: =GEOMEAN(G9:H9) -> 2.2327837e-14 | G9: =(D9*0.000001)/(365*24*3600) -> 2.1245561e-14 | H9: =(E9*0.000001)/(365*24*3600) -> 2.3465246e-14 | I9: =LN(F9) -> -31.432942 | J9: =(LN(H9)-LN(G9))/(2*$K$5) -> 0.019288135
B10: PA_Nylon | C10: =GEOMEAN(D10,E10) -> 3.2 | D10: 0.032 | E10: 320 | F10: =GEOMEAN(G10:H10) -> 1.0147133e-13 | G10: =(D10*0.000001)/(365*24*3600) -> 1.0147133e-15 | H10: =(E10*0.000001)/(365*24*3600) -> 1.0147133e-11 | I10: =LN(F10) -> -29.919 | J10: =(LN(H10)-LN(G10))/(2*$K$5) -> 1.7877213
B11: PET | C11: =GEOMEAN(D11,E11) -> 0.32403703 | D11: 0.001 | E11: 105 | F11: =GEOMEAN(G11:H11) -> 1.0275147e-14 | G11: =(D11*0.000001)/(365*24*3600) -> 3.1709792e-17 | H11: =(E11*0.000001)/(365*24*3600) -> 3.3295282e-12 | I11: =LN(F11) -> -32.209048 | J11: =(LN(H11)-LN(G11))/(2*$K$5) -> 2.2441218
B12: PP | C12: =GEOMEAN(D12,E12) -> 1.2328828 | D12: 0.2 | E12: 7.6 | F12: =GEOMEAN(G12:H12) -> 3.9094457e-14 | G12: =(D12*0.000001)/(365*24*3600) -> 6.3419584e-15 | H12: =(E12*0.000001)/(365*24*3600) -> 2.4099442e-13 | I12: =LN(F12) -> -30.872796 | J12: =(LN(H12)-LN(G12))/(2*$K$5) -> 0.70605321
B13: PS | C13: =GEOMEAN(D13,E13) -> 0.031622777 | D13: 0.001 | E13: 1 | F13: =GEOMEAN(G13:H13) -> 1.0027517e-15 | G13: =(D13*0.000001)/(365*24*3600) -> 3.1709792e-17 | H13: =(E13*0.000001)/(365*24*3600) -> 3.1709792e-14 | I13: =LN(F13) -> -34.536029 | J13: =(LN(H13)-LN(G13))/(2*$K$5) -> 1.340791
B14: PVC | C14: =GEOMEAN(D14,E14) -> 0.01 | D14: 0.001 | E14: 0.1 | F14: =GEOMEAN(G14:H14) -> 3.1709792e-16 | G14: =(D14*0.000001)/(365*24*3600) -> 3.1709792e-17 | H14: =(E14*0.000001)/(365*24*3600) -> 3.1709792e-15 | I14: =LN(F14) -> -35.687321 | J14: =(LN(H14)-LN(G14))/(2*$K$5) -> 0.89386067
B15: PU | C15: =GEOMEAN(D15,E15) -> 0.25248762 | D15: 0.001 | E15: 63.75 | F15: =GEOMEAN(G15:H15) -> 8.00633e-15 | G15: =(D15*0.000001)/(365*24*3600) -> 3.1709792e-17 | H15: =(E15*0.000001)/(365*24*3600) -> 2.0214992e-12 | I15: =LN(F15) -> -32.458544 | J15: =(LN(H15)-LN(G15))/(2*$K$5) -> 2.1472679
B16: PAN | C16: =GEOMEAN(D16,E16) -> 0.01 | D16: 0.001 | E16: 0.1 | F16: =GEOMEAN(G16:H16) -> 3.1709792e-16 | G16: =(D16*0.000001)/(365*24*3600) -> 3.1709792e-17 | H16: =(E16*0.000001)/(365*24*3600) -> 3.1709792e-15 | I16: =LN(F16) -> -35.687321 | J16: =(LN(H16)-LN(G16))/(2*$K$5) -> 0.89386067
B17: TRWP | C17: - | D17: - | E17: - | F17: =GEOMEAN(G17:H17) -> 3.3287916e-15 | G17: 3.16881e-17 | H17: 3.49685e-13 | I17: =LN(F17) -> -33.336167 | J17: =(LN(H17)-LN(G17))/(2*$K$5) -> 1.8068414
B18: PHA | C18: =GEOMEAN(D18,E18) -> 6.1773214 | D18: 0.23 | E18: 165.91 | F18: =GEOMEAN(G18:H18) -> 1.9588158e-13 | G18: =(D18*0.000001)/(365*24*3600) -> 7.2932522e-15 | H18: =(E18*0.000001)/(365*24*3600) -> 5.2609716e-12 | I18: =LN(F18) -> -29.261266 | J18: =(LN(H18)-LN(G18))/(2*$K$5) -> 1.2773916
B19: PLA | C19: =GEOMEAN(D19,E19) -> 0.08660254 | D19: 0.001 | E19: 7.5 | F19: =GEOMEAN(G19:H19) -> 2.7461485e-15 | G19: =(D19*0.000001)/(365*24*3600) -> 3.1709792e-17 | H19: =(E19*0.000001)/(365*24*3600) -> 2.3782344e-13 | I19: =LN(F19) -> -33.528577 | J19: =(LN(H19)-LN(G19))/(2*$K$5) -> 1.7318824
B20: PCL | C20: =GEOMEAN(D20,E20) -> 14.839903 | D20: 1.31416 | E20: 167.5768 | F20: =GEOMEAN(G20:H20) -> 4.7057024e-13 | G20: =(D20*0.000001)/(365*24*3600) -> 4.167174e-14 | H20: =(E20*0.000001)/(365*24*3600) -> 5.3138255e-12 | I20: =LN(F20) -> -28.384831 | J20: =(LN(H20)-LN(G20))/(2*$K$5) -> 0.94104116
B21: PBSA | C21: =GEOMEAN(D21,E21) -> 1.5655184 | D21: 0.608 | E21: 4.031 | F21: =GEOMEAN(G21:H21) -> 4.9642264e-14 | G21: =(D21*0.000001)/(365*24*3600) -> 1.9279554e-14 | H21: =(E21*0.000001)/(365*24*3600) -> 1.2782217e-13 | I21: =LN(F21) -> -30.633934 | J21: =(LN(H21)-LN(G21))/(2*$K$5) -> 0.36715739
B22: starch_blend | C22: 101.29 | D22: =C22/10 -> 10.129 | E22: =C22*10 -> 1012.9 | F22: =GEOMEAN(G22:H22) -> 3.2118848e-12 | G22: =(D22*0.000001)/(365*24*3600) -> 3.2118848e-13 | H22: =(E22*0.000001)/(365*24*3600) -> 3.2118848e-11 | I22: =LN(F22) -> -26.464163 | J22: =(LN(H22)-LN(G22))/(2*$K$5) -> 0.89386067
B23: PBAT | C23: =GEOMEAN(D23,E23) -> 11.752936 | D23: 10.27 | E23: 13.45 | F23: =GEOMEAN(G23:H23) -> 3.7268315e-13 | G23: =(D23*0.000001)/(365*24*3600) -> 3.2565956e-13 | H23: =(E23*0.000001)/(365*24*3600) -> 4.264967e-13 | I23: =LN(F23) -> -28.618048 | J23: =(LN(H23)-LN(G23))/(2*$K$5) -> 0.052358712
B24: Cotton | C24: =GEOMEAN(D24,E24) -> 18.300786 | D24: 5.9971847 | E24: 55.845997 | F24: =GEOMEAN(G24:H24) -> 5.8031411e-13 | G24: =(D24*0.000001)/(365*24*3600) -> 1.9016948e-13 | H24: =(E24*0.000001)/(365*24*3600) -> 1.770865e-12 | I24: =LN(F24) -> -28.175207 | J24: =(LN(H24)-LN(G24))/(2*$K$5) -> 0.43309544
B25: Linen | C25: =GEOMEAN(D25,E25) -> 32.689902 | D25: 21.74 | E25: 49.155 | F25: =GEOMEAN(G25:H25) -> 1.03659e-12 | G25: =(D25*0.000001)/(365*24*3600) -> 6.8937088e-13 | H25: =(E25*0.000001)/(365*24*3600) -> 1.5586948e-12 | I25: =LN(F25) -> -27.595085 | J25: =(LN(H25)-LN(G25))/(2*$K$5) -> 0.15835107
B26: Viscose | C26: =GEOMEAN(D26,E26) -> 24.559331 | D26: 21.922321 | E26: 27.513544 | F26: =GEOMEAN(G26:H26) -> 7.7877128e-13 | G26: =(D26*0.000001)/(365*24*3600) -> 6.9515223e-13 | H26: =(E26*0.000001)/(365*24*3600) -> 8.7244877e-13 | I26: =LN(F26) -> -27.881059 | J26: =(LN(H26)-LN(G26))/(2*$K$5) -> 0.044094154
B27: Rayon | C27: =GEOMEAN(D27,E27) -> 24.559331 | D27: 21.922321 | E27: 27.513544 | F27: =GEOMEAN(G27:H27) -> 7.7877128e-13 | G27: =(D27*0.000001)/(365*24*3600) -> 6.9515223e-13 | H27: =(E27*0.000001)/(365*24*3600) -> 8.7244877e-13 | I27: =LN(F27) -> -27.881059 | J27: =(LN(H27)-LN(G27))/(2*$K$5) -> 0.044094154
B28: Lyocell | C28: =GEOMEAN(D28,E28) -> 39.899771 | D28: 37.799367 | E28: 42.116889 | F28: =GEOMEAN(G28:H28) -> 1.2652134e-12 | G28: =(D28*0.000001)/(365*24*3600) -> 1.1986101e-12 | H28: =(E28*0.000001)/(365*24*3600) -> 1.3355178e-12 | I28: =LN(F28) -> -27.39578 | J28: =(LN(H28)-LN(G28))/(2*$K$5) -> 0.020993104
B29: Modal | C29: =GEOMEAN(D29,E29) -> 51.909814 | D29: 49.834159 | E29: 54.071923 | F29: =GEOMEAN(G29:H29) -> 1.6460494e-12 | G29: =(D29*0.000001)/(365*24*3600) -> 1.5802308e-12 | H29: =(E29*0.000001)/(365*24*3600) -> 1.7146094e-12 | I29: =LN(F29) -> -27.132643 | J29: =(LN(H29)-LN(G29))/(2*$K$5) -> 0.015841305

Sheet 1.3.SSDR_soil
B2: SSDR soil
B4: SSDR values are taken from Louvet et al. (2026), Saadi et al. (2025), Saadi & Boulay (2026), and Corella-Puertas et al. (2023). SBoo requires [m/s] as an input for Kssdr. It is assumed that SSDRs are log-normally distributed (Corella-Puertas et al., 2023), and that the lower to upper limit represents the 99% confidence interval (CI), from which the distribution parameters are derived and used as an input in SBoo (for probabilistic solver). However, when plasticFADE model empirical degradation constants (and their CI) are available, they are used as input to compute degradation rates, ignoring the values below.
I5: log-normal distribution | J5: z_0.995 = | K5: 2.576
B6: Polymer type | C6: Geometric mean SSDR [µm/year] | D6: Lower limit SSDR [µm/year] | E6: Upper limit SSDR [µm/year] | F6: Geometric mean SSDR [m/s] | G6: Lower limit SSDR [m/s] | H6: Upper limit SSDR [m/s] | I6: mu | J6: sigma | K6: Note
B7: EPS | C7: =GEOMEAN(D7,E7) -> 0.031622777 | D7: 0.001 | E7: 1 | F7: =GEOMEAN(G7:H7) -> 1.0027517e-15 | G7: =(D7*0.000001)/(365*24*3600) -> 3.1709792e-17 | H7: =(E7*0.000001)/(365*24*3600) -> 3.1709792e-14 | I7: =LN(F7) -> -34.536029 | J7: =(LN(H7)-LN(G7))/(2*$K$5) -> 1.340791
B8: HDPE | C8: =GEOMEAN(D8,E8) -> 1.1401754 | D8: 1 | E8: 1.3 | F8: =GEOMEAN(G8:H8) -> 3.6154726e-14 | G8: =(D8*0.000001)/(365*24*3600) -> 3.1709792e-14 | H8: =(E8*0.000001)/(365*24*3600) -> 4.122273e-14 | I8: =LN(F8) -> -30.950969 | J8: =(LN(H8)-LN(G8))/(2*$K$5) -> 0.050924741
B9: LDPE | C9: =GEOMEAN(D9,E9) -> 15.556349 | D9: 11 | E9: 22 | F9: =GEOMEAN(G9:H9) -> 4.932886e-13 | G9: =(D9*0.000001)/(365*24*3600) -> 3.4880771e-13 | H9: =(E9*0.000001)/(365*24*3600) -> 6.9761542e-13 | I9: =LN(F9) -> -28.337682 | J9: =(LN(H9)-LN(G9))/(2*$K$5) -> 0.13453944
B10: PA_Nylon | C10: =GEOMEAN(D10,E10) -> 3.2 | D10: 0.032 | E10: 320 | F10: =GEOMEAN(G10:H10) -> 1.0147133e-13 | G10: =(D10*0.000001)/(365*24*3600) -> 1.0147133e-15 | H10: =(E10*0.000001)/(365*24*3600) -> 1.0147133e-11 | I10: =LN(F10) -> -29.919 | J10: =(LN(H10)-LN(G10))/(2*$K$5) -> 1.7877213
B11: PET | C11: =GEOMEAN(D11,E11) -> 0.59219929 | D11: 0.21 | E11: 1.67 | F11: =GEOMEAN(G11:H11) -> 1.8778516e-14 | G11: =(D11*0.000001)/(365*24*3600) -> 6.6590563e-15 | H11: =(E11*0.000001)/(365*24*3600) -> 5.2955353e-14 | I11: =LN(F11) -> -31.606063 | J11: =(LN(H11)-LN(G11))/(2*$K$5) -> 0.40245951
B12: PP | C12: =GEOMEAN(D12,E12) -> 0.69107852 | D12: 0.29775984 | E12: 1.603942 | F12: =GEOMEAN(G12:H12) -> 2.1913956e-14 | G12: =(D12*0.000001)/(365*24*3600) -> 9.4419026e-15 | H12: =(E12*0.000001)/(365*24*3600) -> 5.0860667e-14 | I12: =LN(F12) -> -31.451653 | J12: =(LN(H12)-LN(G12))/(2*$K$5) -> 0.32685023
B13: PS | C13: =GEOMEAN(D13,E13) -> 0.031622777 | D13: 0.001 | E13: 1 | F13: =GEOMEAN(G13:H13) -> 1.0027517e-15 | G13: =(D13*0.000001)/(365*24*3600) -> 3.1709792e-17 | H13: =(E13*0.000001)/(365*24*3600) -> 3.1709792e-14 | I13: =LN(F13) -> -34.536029 | J13: =(LN(H13)-LN(G13))/(2*$K$5) -> 1.340791
B14: PVC | C14: =GEOMEAN(D14,E14) -> 0.01 | D14: 0.001 | E14: 0.1 | F14: =GEOMEAN(G14:H14) -> 3.1709792e-16 | G14: =(D14*0.000001)/(365*24*3600) -> 3.1709792e-17 | H14: =(E14*0.000001)/(365*24*3600) -> 3.1709792e-15 | I14: =LN(F14) -> -35.687321 | J14: =(LN(H14)-LN(G14))/(2*$K$5) -> 0.89386067
B15: PU | C15: =GEOMEAN(D15,E15) -> 0.25248762 | D15: 0.001 | E15: 63.75 | F15: =GEOMEAN(G15:H15) -> 8.00633e-15 | G15: =(D15*0.000001)/(365*24*3600) -> 3.1709792e-17 | H15: =(E15*0.000001)/(365*24*3600) -> 2.0214992e-12 | I15: =LN(F15) -> -32.458544 | J15: =(LN(H15)-LN(G15))/(2*$K$5) -> 2.1472679
B16: PAN | C16: =GEOMEAN(D16,E16) -> 0.01 | D16: 0.001 | E16: 0.1 | F16: =GEOMEAN(G16:H16) -> 3.1709792e-16 | G16: =(D16*0.000001)/(365*24*3600) -> 3.1709792e-17 | H16: =(E16*0.000001)/(365*24*3600) -> 3.1709792e-15 | I16: =LN(F16) -> -35.687321 | J16: =(LN(H16)-LN(G16))/(2*$K$5) -> 0.89386067
B17: TRWP | C17: - | D17: - | E17: - | F17: =GEOMEAN(G17:H17) -> 2.6740142e-13 | G17: 6.15047e-14 | H17: 1.16257e-12 | I17: =LN(F17) -> -28.950025 | J17: =(LN(H17)-LN(G17))/(2*$K$5) -> 0.5705114
B18: PHA | C18: =GEOMEAN(D18,E18) -> 1194.7446 | D18: 912.5 | E18: 1564.29 | F18: =GEOMEAN(G18:H18) -> 3.7885102e-11 | G18: =(D18*0.000001)/(365*24*3600) -> 2.8935185e-11 | H18: =(E18*0.000001)/(365*24*3600) -> 4.9603311e-11 | I18: =LN(F18) -> -23.996463 | J18: =(LN(H18)-LN(G18))/(2*$K$5) -> 0.10461942
B19: PLA | C19: =GEOMEAN(D19,E19) -> 121.05227 | D19: 78.69 | E19: 186.22 | F19: =GEOMEAN(G19:H19) -> 3.8385423e-12 | G19: =(D19*0.000001)/(365*24*3600) -> 2.4952435e-12 | H19: =(E19*0.000001)/(365*24*3600) -> 5.9049975e-12 | I19: =LN(F19) -> -26.285928 | J19: =(LN(H19)-LN(G19))/(2*$K$5) -> 0.16719967
B20: PCL | C20: =GEOMEAN(D20,E20) -> 14.839903 | D20: 1.31416 | E20: 167.5768 | F20: =GEOMEAN(G20:H20) -> 4.7057024e-13 | G20: =(D20*0.000001)/(365*24*3600) -> 4.167174e-14 | H20: =(E20*0.000001)/(365*24*3600) -> 5.3138255e-12 | I20: =LN(F20) -> -28.384831 | J20: =(LN(H20)-LN(G20))/(2*$K$5) -> 0.94104116
B21: PBSA | C21: =GEOMEAN(D21,E21) -> 44.72287 | D21: 39.673913 | E21: 50.414365 | F21: =GEOMEAN(G21:H21) -> 1.4181529e-12 | G21: =(D21*0.000001)/(365*24*3600) -> 1.2580515e-12 | H21: =(E21*0.000001)/(365*24*3600) -> 1.598629e-12 | I21: =LN(F21) -> -27.281666 | J21: =(LN(H21)-LN(G21))/(2*$K$5) -> 0.046502771
B22: starch_blend | C22: 101.29 | D22: 42.74 | E22: 2556.9 | F22: =GEOMEAN(G22:H22) -> 1.0482564e-11 | G22: =(D22*0.000001)/(365*24*3600) -> 1.3552765e-12 | H22: =(E22*0.000001)/(365*24*3600) -> 8.1078767e-11 | I22: =LN(F22) -> -25.281308 | J22: =(LN(H22)-LN(G22))/(2*$K$5) -> 0.79414123
B23: PBAT | C23: =GEOMEAN(D23,E23) -> 5.4221767 | D23: 1.96 | E23: 15 | F23: =GEOMEAN(G23:H23) -> 1.7193609e-13 | G23: =(D23*0.000001)/(365*24*3600) -> 6.2151192e-14 | H23: =(E23*0.000001)/(365*24*3600) -> 4.7564688e-13 | I23: =LN(F23) -> -29.391654 | J23: =(LN(H23)-LN(G23))/(2*$K$5) -> 0.39501276
B24: Cotton | C24: =GEOMEAN(D24,E24) -> 3.9632422 | D24: =H35 -> 1.8766595 | E24: =H36 -> 8.3698127 | F24: =GEOMEAN(G24:H24) -> 1.2567359e-13 | G24: =(D24*0.000001)/(365*24*3600) -> 5.9508483e-14 | H24: =(E24*0.000001)/(365*24*3600) -> 2.6540502e-13 | I24: =LN(F24) -> -29.705088 | J24: =(LN(H24)-LN(G24))/(2*$K$5) -> 0.29020539
B25: Linen | C25: =GEOMEAN(D25,E25) -> 3.9632422 | D25: =D24 -> 1.8766595 | E25: =E24 -> 8.3698127 | F25: =GEOMEAN(G25:H25) -> 1.2567359e-13 | G25: =(D25*0.000001)/(365*24*3600) -> 5.9508483e-14 | H25: =(E25*0.000001)/(365*24*3600) -> 2.6540502e-13 | I25: =LN(F25) -> -29.705088 | J25: =(LN(H25)-LN(G25))/(2*$K$5) -> 0.29020539 | K25: No degradation data in soil available. The SSDR of cotton was chosen as a proxy, given their common cellulosic composition
B26: Viscose | C26: =GEOMEAN(D26,E26) -> 3.9632422 | D26: =D25 -> 1.8766595 | E26: =E25 -> 8.3698127 | F26: =GEOMEAN(G26:H26) -> 1.2567359e-13 | G26: =(D26*0.000001)/(365*24*3600) -> 5.9508483e-14 | H26: =(E26*0.000001)/(365*24*3600) -> 2.6540502e-13 | I26: =LN(F26) -> -29.705088 | J26: =(LN(H26)-LN(G26))/(2*$K$5) -> 0.29020539
B27: Rayon | C27: =GEOMEAN(D27,E27) -> 3.9632422 | D27: =D26 -> 1.8766595 | E27: =E26 -> 8.3698127 | F27: =GEOMEAN(G27:H27) -> 1.2567359e-13 | G27: =(D27*0.000001)/(365*24*3600) -> 5.9508483e-14 | H27: =(E27*0.000001)/(365*24*3600) -> 2.6540502e-13 | I27: =LN(F27) -> -29.705088 | J27: =(LN(H27)-LN(G27))/(2*$K$5) -> 0.29020539
B28: Lyocell | C28: =GEOMEAN(D28,E28) -> 3.9632422 | D28: =D27 -> 1.8766595 | E28: =E27 -> 8.3698127 | F28: =GEOMEAN(G28:H28) -> 1.2567359e-13 | G28: =(D28*0.000001)/(365*24*3600) -> 5.9508483e-14 | H28: =(E28*0.000001)/(365*24*3600) -> 2.6540502e-13 | I28: =LN(F28) -> -29.705088 | J28: =(LN(H28)-LN(G28))/(2*$K$5) -> 0.29020539
B29: Modal | C29: =GEOMEAN(D29,E29) -> 3.9632422 | D29: =D28 -> 1.8766595 | E29: =E28 -> 8.3698127 | F29: =GEOMEAN(G29:H29) -> 1.2567359e-13 | G29: =(D29*0.000001)/(365*24*3600) -> 5.9508483e-14 | H29: =(E29*0.000001)/(365*24*3600) -> 2.6540502e-13 | I29: =LN(F29) -> -29.705088 | J29: =(LN(H29)-LN(G29))/(2*$K$5) -> 0.29020539
B32: Additional SSDRs are computed, based on the approach of Maga et al. (2022)
B34: Material | C34: Reference | D34: shape factor (1, 2, 3) | E34: % Reduction in mass | F34: time (yr) | G34: Initial size (um) | H34: SSDR (um/yr) | I34: SSDR (m/s)
B35: Cotton | C35: Smith et al. (2021) | D35: 2 | E35: 0.2 | F35: =154/365 -> 0.42191781 | G35: 15 | H35: =1/2*G35/F35*(1-(1-E35)^(1/D35)) -> 1.8766595 | I35: =H35/(365*24*3600)/1000000 -> 5.9508483e-14
B36: Cotton | C36: Smith et al. (2021) | D36: 2 | E36: 0.72 | F36: =154/365 -> 0.42191781 | G36: 15 | H36: =1/2*G36/F36*(1-(1-E36)^(1/D36)) -> 8.3698127 | I36: =H36/(365*24*3600)/1000000 -> 2.6540502e-13
B37: Cotton | C37: Li et al. (2010) | D37: 2 | E37: 0.16 | F37: =90/365 -> 0.24657534 | G37: 15 | H37: =1/2*G37/F37*(1-(1-E37)^(1/D37)) -> 2.5393312 | I37: =H37/(365*24*3600)/1000000 -> 8.0521664e-14
B38: Cotton | C38: Li et al. (2010) | D38: 2 | E38: 0.28 | F38: =90/365 -> 0.24657534 | G38: 15 | H38: =1/2*G38/F38*(1-(1-E38)^(1/D38)) -> 4.6072692 | I38: =H38/(365*24*3600)/1000000 -> 1.4609555e-13

Sheet 1.4.plasticFADE constants
B2: PlasticFADE
B4: plasticFADE empirical constants are taken from Tang & Boulay (under review). SBoo requires the empirical constants as an input. To derive the uncertainty associated with the degradation model, the mean and standard deviation of plasticFADE are used. The standard deviation defined in plasticFADE corresponds to the std. dev. of normal distribution in log-space, while the fitted value is the mean value from which we take the log.
C6: HDPE | G6: LDPE | K6: PET | O6: PP | S6: PS
B7: Polymer type | C7: Fitted value | D7: Standard deviation | E7: mu | F7: sigma | G7: Fitted value | H7: Standard deviation | I7: mu | J7: sigma | K7: Fitted value | L7: Standard deviation | M7: mu | N7: sigma | O7: Fitted value | P7: Standard deviation | Q7: mu | R7: sigma | S7: Fitted value | T7: Standard deviation | U7: mu | V7: sigma
B8: degx | C8: 0.010262753 | D8: 0.00088522569 | E8: =LN(C8) -> -4.5792341 | F8: =D8 -> 0.00088522569 | G8: 0.01105059 | H8: 0.0057046217 | I8: =LN(G8) -> -4.5052715 | J8: =H8 -> 0.0057046217 | K8: 0.00024327627 | L8: 0.00029524826 | M8: =LN(K8) -> -8.3213129 | N8: =L8 -> 0.00029524826 | O8: 0.0054981915 | P8: 0.0050951617 | Q8: =LN(O8) -> -5.2033361 | R8: =P8 -> 0.0050951617 | S8: 0.00027325415 | T8: 0.00020039698 | U8: =LN(S8) -> -8.2051082 | V8: =T8 -> 0.00020039698
B9: degtau | C9: 3.3584081e-11 | D9: 0.18031552 | E9: =LN(C9) -> -24.116969 | F9: =D9 -> 0.18031552 | G9: 5e-13 | H9: 0.10974721 | I9: =LN(G9) -> -28.324168 | J9: =H9 -> 0.10974721 | K9: 0.79097577 | L9: 0.1933289 | M9: =LN(K9) -> -0.23448794 | N9: =L9 -> 0.1933289 | O9: 0.013720791 | P9: 0.11216725 | Q9: =LN(O9) -> -4.288843 | R9: =P9 -> 0.11216725 | S9: 0.24329239 | T9: 0.067550473 | U9: =LN(S9) -> -1.4134913 | V9: =T9 -> 0.067550473
B10: degy | C10: 0.0021825284 | D10: 0.004283861 | E10: =LN(C10) -> -6.1272713 | F10: =D10 -> 0.004283861 | G10: 0.01031456 | H10: 0.0061122893 | I10: =LN(G10) -> -4.5741988 | J10: =H10 -> 0.0061122893 | K10: 1.3261956e-05 | L10: 2.1960389e-05 | M10: =LN(K10) -> -11.230611 | N10: =L10 -> 2.1960389e-05 | O10: 0.01724523 | P10: 0.0016245855 | Q10: =LN(O10) -> -4.0602197 | R10: =P10 -> 0.0016245855 | S10: 0.014446952 | T10: 4.3872181e-06 | U10: =LN(S10) -> -4.2372718 | V10: =T10 -> 4.3872181e-06
B11: degtheta | C11: 0.29904863 | D11: 0.56576349 | E11: =LN(C11) -> -1.2071491 | F11: =D11 -> 0.56576349 | G11: 0.0043620223 | H11: 3.6211087e-05 | I11: =LN(G11) -> -5.4348195 | J11: =H11 -> 3.6211087e-05 | K11: 1.8763022 | L11: 0.22318783 | M11: =LN(K11) -> 0.62930293 | N11: =L11 -> 0.22318783 | O11: 0.70549282 | P11: 0.3804722 | Q11: =LN(O11) -> -0.34885869 | R11: =P11 -> 0.3804722 | S11: 1.0090732 | T11: 0.16004413 | U11: =LN(S11) -> 0.0090322632 | V11: =T11 -> 0.16004413
B12: degz | C12: 0.00037803206 | D12: 0.0010821863 | E12: =LN(C12) -> -7.8805316 | F12: =D12 -> 0.0010821863 | G12: 0.00010475543 | H12: 0.00044412819 | I12: =LN(G12) -> -9.1638822 | J12: =H12 -> 0.00044412819 | K12: 0.015217891 | L12: 4.4013893e-06 | M12: =LN(K12) -> -4.1852835 | N12: =L12 -> 4.4013893e-06 | O12: 1.6158544e-05 | P12: 3.8147496e-05 | Q12: =LN(O12) -> -11.033062 | R12: =P12 -> 3.8147496e-05 | S12: 6.2330522e-05 | T12: 0.00017657694 | U12: =LN(S12) -> -9.6830593 | V12: =T12 -> 0.00017657694
B13: degeta | C13: 0.21648777 | D13: 0.17415974 | E13: =LN(C13) -> -1.5302212 | F13: =D13 -> 0.17415974 | G13: 0.32405972 | H13: 0.19223313 | I13: =LN(G13) -> -1.1268275 | J13: =H13 -> 0.19223313 | K13: 0.07846195 | L13: 0.045684842 | M13: =LN(K13) -> -2.5451415 | N13: =L13 -> 0.045684842 | O13: 0.44210919 | P13: 0.11138573 | Q13: =LN(O13) -> -0.8161984 | R13: =P13 -> 0.11138573 | S13: 0.49603679 | T13: 0.1221179 | U13: =LN(S13) -> -0.70110518 | V13: =T13 -> 0.1221179

Sheet 2.1. Sed_rates
B2: Default sedimentation rates for low-density polymers
B4: Default sedimentation rates are taken from Corella-Puertas et al. (2023). They are only used when SBoo returns a settling velocity of 0 m/s (for particles with density lower than that of water). For the marine environment, these default settling velocities are not used, as TrackMPD is used to derive settling velocities.
D5: 100 | E5: m
B6: polymer type | C6: default sed rate [s-1] | D6: default sed velocity [m.s-1]
B7: EPS | C7: 8.35e-13 | D7: =C7*$D$5 -> 8.35e-11 | E7: m/s
B8: PP | C8: 5.67e-10 | D8: =C8*$D$5 -> 5.67e-08 | E8: m/s
B9: HDPE | C9: 5.67e-10 | D9: =C9*$D$5 -> 5.67e-08 | E9: m/s
B10: LDPE | C10: 5.67e-10 | D10: =C10*$D$5 -> 5.67e-08 | E10: m/s

Sheet 4.1.Regio_param (2)
B2: Regionalization parameters
A4: regions | B4: CONTINENTAL SCALE | U4: GLOBAL SCALE
A5: parameter | B5: area_land_C | C5: area_sea_C | D5: areafrac_rw_C | E5: areafrac_lw_C | F5: areafrac_nat_soil_C | G5: areafrac_agr_soil_C | H5: fracsf_rw_C | I5: fracsf_lw_C | J5: temp_C | K5: wind_speed_C | L5: rain_rate_C | M5: depth_rw_C | N5: depth_lw_C | O5: depth_sw_C | P5: frac_runoff_rw_C | Q5: frac_runoff_lw_C | R5: frac_infiltr_C | S5: soil_ero_C | T5: irrig_C | U5: area_land_G | V5: area_sea_G | W5: areafrac_rw_G | X5: areafrac_lw_G | Y5: areafrac_nat_soil_G | Z5: areafrac_agr_soil_G | AA5: fracsf_rw_G | AB5: fracsf_lw_G | AC5: temp_G | AD5: wind_speed_G | AE5: rain_rate_G | AF5: depth_rw_G | AG5: depth_lw_G | AH5: depth_sw_G | AI5: frac_runoff_rw_G | AJ5: frac_runoff_lw_G | AK5: frac_infiltr_G | AL5: soil_ero_G | AM5: irrig_G | AO5: depth soil | AP5: 0.1
A6: description | B6: area of land | C6: area of sea | D6: fraction of land area allocated to river | E6: fraction of land area allocated to lake | F6: fraction of land area allocated to natural soil | G6: fraction of land area allocated to agricultural soil | H6: fraction of surface water allocated to river | I6: fraction of surface water allocated to lake | J6: temperature | K6: wind speed | L6: rain rate | M6: depth river water | N6: depth lake water | O6: depth sea water | P6: fraction runoff to river | Q6: fraction runoff to lake | R6: fraction infiltration | S6: soil erosion | T6: irrigation | U6: area of land | V6: area of sea | W6: fraction of land area allocated to river | X6: fraction of land area allocated to lake | Y6: fraction of land area allocated to natural soil | Z6: fraction of land area allocated to agricultural soil | AA6: fraction of surface water allocated to river | AB6: fraction of surface water allocated to lake | AC6: temperature | AD6: wind speed | AE6: rain rate | AF6: depth river water | AG6: depth lake water | AH6: depth sea water | AI6: fraction runoff to river | AJ6: fraction runoff to lake | AK6: fraction infiltration | AL6: soil erosion | AM6: irrigation
A7: unit | B7: [m2] | C7: [m2] | D7: - | E7: - | F7: - | G7: - | H7: - | I7: - | J7: K | K7: [m*s-1] | L7: [m*s-1] | M7: [m] | N7: [m] | O7: [m] | P7: - | Q7: - | R7: - | S7: [m*s-1] | T7: [m3] | U7: [m2] | V7: [m2] | W7: - | X7: - | Y7: - | Z7: - | AA7: - | AB7: - | AC7: K | AD7: [m*s-1] | AE7: [m*s-1] | AF7: [m] | AG7: [m] | AH7: [m] | AI7: - | AJ7: - | AK7: - | AL7: [m*s-1] | AM7: [m3] | AO7: marine | AR7: freshwater | AU7: terrestrial
A8: source | B8: USEtox | C8: USEtox | D8: Calculated with HydroATLAS | E8: Calculated with HydroATLAS | F8: USEtox | G8: USEtox | H8: Calculated with HydroATLAS | I8: Calculated with HydroATLAS | J8: USEtox | K8: USEtox | L8: USEtox | M8: Calculated with HydroATLAS | N8: Calculated with HydroATLAS | O8: USEtox | P8: Fraction runoff in USEtox * Fraction of surface water allocated to river | Q8: Fraction runoff in USEtox * Fraction of surface water allocated to lake | R8: USEtox | S8: USEtox | T8: USEtox | U8: USEtox | V8: USEtox | W8: Calculated with HydroATLAS | X8: Calculated with HydroATLAS | Y8: USEtox | Z8: USEtox | AA8: Calculated with HydroATLAS | AB8: Calculated with HydroATLAS | AC8: USEtox | AD8: USEtox | AE8: USEtox | AF8: Calculated with HydroATLAS | AG8: Calculated with HydroATLAS | AH8: USEtox | AI8: Fraction runoff in USEtox * Fraction of surface water allocated to river | AJ8: Fraction runoff in USEtox * Fraction of surface water allocated to lake | AK8: USEtox | AL8: USEtox | AM8: USEtox | AO8: continental | AP8: global | AQ8: total | AR8: continental | AS8: global | AT8: total | AU8: continental | AV8: global | AW8: total
A9: North America | B9: 1.448998e+13 | C9: 1.8374074e+12 | D9: 0.0034304356 | E9: 0.083169844 | F9: 0.63128839 | G9: 0.28211133 | H9: 0.039612292 | I9: 0.96038771 | J9: 285.15 | K9: 3 | L9: 2.2427398e-08 | M9: 2.3696042 | N9: 29.533 | O9: 100 | P9: 0.014496812 | Q9: 0.3514707 | R9: 0.26947836 | S9: 9.5129376e-13 | T9: 1.9675113e+11 | U9: 1.2391012e+14 | V9: 3.6203119e+14 | W9: 0.0037256943 | X9: 0.023643521 | Y9: 0.60856223 | Z9: 0.36406856 | AA9: 0.13612719 | AB9: 0.86387281 | AC9: 285.15 | AD9: 3 | AE9: 2.2196854e-08 | AF9: 3.3481105 | AG9: 90.805257 | AH9: 3682 | AI9: 0.034031797 | AJ9: 0.2159682 | AK9: 0.25 | AL9: 9.5129376e-13 | AM9: 2722000000000 | AO9: =C9*O9 -> 183740737794961 | AP9: =V9*AH9 -> 1.3329988e+18 | AQ9: =AP9+AO9 -> 1.3331826e+18 | AR9: =B9*E9*N9+B9*D9*M9 -> 3.5708871e+13 | AS9: =U9*X9*AG9+U9*W9*AF9 -> 2.6757523e+14 | AT9: =AS9+AR9 -> 3.032841e+14 | AU9: =B9*F9*$AP$5+B9*G9*$AP$5 -> 1.3235143e+12 | AV9: =U9*Y9*$AP$5+U9*Z9*$AP$5 -> 1.2051879e+13 | AW9: =AV9+AU9 -> 1.3375394e+13
A10: Latin America | B10: 2.08779e+13 | C10: 2.9728967e+12 | D10: 0.0064487285 | E10: 0.012684412 | F10: 0.65377256 | G10: 0.3270943 | H10: 0.33704496 | I10: 0.66295504 | J10: 285.15 | K10: 3 | L10: 5.1120312e-08 | M10: 4.3917246 | N10: 25.706 | O10: 100 | P10: 0.12852081 | Q10: 0.25279571 | R10: 0.26947836 | S10: 9.5129376e-13 | T10: 232770200000 | U10: 1.175222e+14 | V10: 3.608957e+14 | W10: 0.0027612917 | X10: 0.033374003 | Y10: 0.60333262 | Z10: 0.36053209 | AA10: 0.076415366 | AB10: 0.92358463 | AC10: 285.15 | AD10: 3 | AE10: 2.2196854e-08 | AF10: 2.7350201 | AG10: 66.519703 | AH10: 3682 | AI10: 0.019103841 | AJ10: 0.23089616 | AK10: 0.25 | AL10: 9.5129376e-13 | AM10: 2722000000000 | AO10: =C10*O10 -> 297289672214318 | AP10: =V10*AH10 -> 1.328818e+18 | AQ10: =AP10+AO10 -> 1.3291152e+18 | AR10: =B10*E10*N10+B10*D10*M10 -> 7.3988466e+12 | AS10: =U10*X10*AG10+U10*W10*AF10 -> 2.617902e+14 | AT10: =AS10+AR10 -> 2.6918905e+14 | AU10: =B10*F10*$AP$5+B10*G10*$AP$5 -> 2.047844e+12 | AV10: =U10*Y10*$AP$5+U10*Z10*$AP$5 -> 1.132755e+13 | AW10: =AV10+AU10 -> 1.3375394e+13
A11: Europe | B11: 8.5662136e+12 | C11: 1.7001869e+12 | D11: 0.0050055029 | E11: 0.025460718 | F11: 0.584526 | G11: 0.38500778 | H11: 0.16429681 | I11: 0.83570319 | J11: 285.15 | K11: 3 | L11: 1.7523958e-08 | M11: 1.9467369 | N11: 26.89 | O11: 100 | P11: 0.028291286 | Q11: 0.14390491 | R11: 0.26947836 | S11: 9.5129376e-13 | T11: 1.154305e+11 | U11: 1.2983388e+14 | V11: 3.6216841e+14 | W11: 0.0032048504 | X11: 0.030570453 | Y11: 0.61268443 | Z11: 0.35354027 | AA11: 0.094887391 | AB11: 0.90511261 | AC11: 285.15 | AD11: 3 | AE11: 2.2196854e-08 | AF11: 3.2415889 | AG11: 65.10935 | AH11: 3682 | AI11: 0.023721848 | AJ11: 0.22627815 | AK11: 0.25 | AL11: 9.5129376e-13 | AM11: 2722000000000 | AO11: =C11*O11 -> 170018686238713 | AP11: =V11*AH11 -> 1.3335041e+18 | AQ11: =AP11+AO11 -> 1.3336741e+18 | AR11: =B11*E11*N11+B11*D11*M11 -> 5.9482339e+12 | AS11: =U11*X11*AG11+U11*W11*AF11 -> 2.5977308e+14 | AT11: =AS11+AR11 -> 2.6572131e+14 | AU11: =B11*F11*$AP$5+B11*G11*$AP$5 -> 8.3052334e+11 | AV11: =U11*Y11*$AP$5+U11*Z11*$AP$5 -> 1.254487e+13 | AW11: =AV11+AU11 -> 1.3375394e+13
A12: Africa & Middle East | B12: 3.429833e+13 | C12: 1.5904011e+12 | D12: 0.00013076169 | E12: 0.013897746 | F12: 0.58847302 | G12: 0.39749848 | H12: 0.0093211403 | I12: 0.99067886 | J12: 285.15 | K12: 3 | L12: 2.0870339e-08 | M12: 2.4790569 | N12: 115.865 | O12: 100 | P12: 0.0017166348 | Q12: 0.18244911 | R12: 0.26947836 | S12: 9.5129376e-13 | T12: 272246800000 | U12: 1.0410177e+14 | V12: 3.6227819e+14 | W12: 0.0041965315 | X12: 0.03581244 | Y12: 0.61834427 | Z12: 0.34164676 | AA12: 0.10488976 | AB12: 0.89511024 | AC12: 285.15 | AD12: 3 | AE12: 2.2196854e-08 | AF12: 3.1902083 | AG12: 58.82413 | AH12: 3682 | AI12: 0.026222441 | AJ12: 0.22377756 | AK12: 0.25 | AL12: 9.5129376e-13 | AM12: 2722000000000 | AO12: =C12*O12 -> 159040112105118 | AP12: =V12*AH12 -> 1.3339083e+18 | AQ12: =AP12+AO12 -> 1.3340673e+18 | AR12: =B12*E12*N12+B12*D12*M12 -> 5.5240427e+13 | AS12: =U12*X12*AG12+U12*W12*AF12 -> 2.2069818e+14 | AT12: =AS12+AR12 -> 2.7593861e+14 | AU12: =B12*F12*$AP$5+B12*G12*$AP$5 -> 3.3817176e+12 | AV12: =U12*Y12*$AP$5+U12*Z12*$AP$5 -> 9.9936761e+12 | AW12: =AV12+AU12 -> 1.3375394e+13
A13: Central Asia | B13: 1.6876936e+13 | C13: 7.3629569e+11 | D13: 0.0022461359 | E13: 0.027333048 | F13: 0.5213891 | G13: 0.44903172 | H13: 0.075936371 | I13: 0.92406363 | J13: 285.15 | K13: 3 | L13: 6.9029435e-09 | M13: 2.2211414 | N13: 33.135 | O13: 100 | P13: 0.035221577 | Q13: 0.42860856 | R13: 0.26947836 | S13: 9.5129376e-13 | T13: 2.2477736e+11 | U13: 1.2152316e+14 | V13: 3.631323e+14 | W13: 0.0033368619 | X13: 0.030787933 | Y13: 0.62337847 | Z13: 0.34249673 | AA13: 0.097784086 | AB13: 0.90221591 | AC13: 285.15 | AD13: 3 | AE13: 2.2196854e-08 | AF13: 3.2236167 | AG13: 65.859719 | AH13: 3682 | AI13: 0.024446021 | AJ13: 0.22555398 | AK13: 0.25 | AL13: 9.5129376e-13 | AM13: 2722000000000 | AO13: =C13*O13 -> 7.3629569e+13 | AP13: =V13*AH13 -> 1.3370531e+18 | AQ13: =AP13+AO13 -> 1.3371267e+18 | AR13: =B13*E13*N13+B13*D13*M13 -> 1.5369311e+13 | AS13: =U13*X13*AG13+U13*W13*AF13 -> 2.4771784e+14 | AT13: =AS13+AR13 -> 2.6308715e+14 | AU13: =B13*F13*$AP$5+B13*G13*$AP$5 -> 1.637773e+12 | AV13: =U13*Y13*$AP$5+U13*Z13*$AP$5 -> 1.1737621e+13 | AW13: =AV13+AU13 -> 1.3375394e+13
A14: Southeast Asia | B14: 1.6866064e+13 | C14: 5.3374046e+12 | D14: 0.012328111 | E14: 0.026854951 | F14: 0.49742035 | G14: 0.46339659 | H14: 0.31462858 | I14: 0.68537142 | J14: 285.15 | K14: 3 | L14: 4.8075939e-08 | M14: 3.3070096 | N14: 17.388 | O14: 100 | P14: 0.082847468 | Q14: 0.18047085 | R14: 0.26947836 | S14: 9.5129376e-13 | T14: 1.6684885e+12 | U14: 1.2153403e+14 | V14: 3.5853119e+14 | W14: 0.0026678907 | X14: 0.030123706 | Y14: 0.62669565 | Z14: 0.34051276 | AA14: 0.081358975 | AB14: 0.91864103 | AC14: 285.15 | AD14: 3 | AE14: 2.2196854e-08 | AF14: 3.1509464 | AG14: 66.64602 | AH14: 3682 | AI14: 0.020339744 | AJ14: 0.22966026 | AK14: 0.25 | AL14: 9.5129376e-13 | AM14: 2722000000000 | AO14: =C14*O14 -> 5.3374046e+14 | AP14: =V14*AH14 -> 1.3201118e+18 | AQ14: =AP14+AO14 -> 1.3206456e+18 | AR14: =B14*E14*N14+B14*D14*M14 -> 8.5632896e+12 | AS14: =U14*X14*AG14+U14*W14*AF14 -> 2.4501643e+14 | AT14: =AS14+AR14 -> 2.5357972e+14 | AU14: =B14*F14*$AP$5+B14*G14*$AP$5 -> 1.62052e+12 | AV14: =U14*Y14*$AP$5+U14*Z14*$AP$5 -> 1.1754874e+13 | AW14: =AV14+AU14 -> 1.3375394e+13
A15: Northern regions | B15: 1.8299925e+13 | C15: 5.6248619e+12 | D15: 0.0046867292 | E15: 0.051861908 | F15: 0.82125082 | G15: 0.12220054 | H15: 0.082879614 | I15: 0.91712039 | J15: 285.15 | K15: 3 | L15: 1.5527965e-08 | M15: 2.9280377 | N15: 131.869 | O15: 100 | P15: 0.029771738 | Q15: 0.32944492 | R15: 0.26947836 | S15: 9.5129376e-13 | T15: 9.689203e+08 | U15: 1.2010017e+14 | V15: 3.5824373e+14 | W15: 0.0030580701 | X15: 0.027011189 | Y15: 0.57889629 | Z15: 0.39103445 | AA15: 0.10170088 | AB15: 0.89829912 | AC15: 285.15 | AD15: 3 | AE15: 2.2196854e-08 | AF15: 3.2600325 | AG15: 39.143976 | AH15: 3682 | AI15: 0.02542522 | AJ15: 0.22457478 | AK15: 0.25 | AL15: 9.5129376e-13 | AM15: 2722000000000 | AO15: =C15*O15 -> 562486190588604 | AP15: =V15*AH15 -> 1.3190534e+18 | AQ15: =AP15+AO15 -> 1.3196159e+18 | AR15: =B15*E15*N15+B15*D15*M15 -> 1.2540391e+14 | AS15: =U15*X15*AG15+U15*W15*AF15 -> 1.2818228e+14 | AT15: =AS15+AR15 -> 2.5358619e+14 | AU15: =B15*F15*$AP$5+B15*G15*$AP$5 -> 1.7265089e+12 | AV15: =U15*Y15*$AP$5+U15*Z15*$AP$5 -> 1.1648885e+13 | AW15: =AV15+AU15 -> 1.3375394e+13
A16: Oceania | B16: 8.1247481e+12 | C16: 2.2405685e+12 | D16: 0.0008998234 | E16: 0.0058477675 | F16: 0.53527812 | G16: 0.45797429 | H16: 0.13335477 | I16: 0.86664523 | J16: 285.15 | K16: 3 | L16: 4.1085817e-08 | M16: 1.0055754 | N16: 8.809 | O16: 100 | P16: 0.025343262 | Q16: 0.16470065 | R16: 0.26947836 | S16: 9.5129376e-13 | T16: 1.0566e+10 | U16: 1.3027535e+14 | V16: 3.6162802e+14 | W16: 0.0033812262 | X16: 0.031862099 | Y16: 0.6156604 | Z16: 0.34909628 | AA16: 0.095939476 | AB16: 0.90406052 | AC16: 285.15 | AD16: 3 | AE16: 2.2196854e-08 | AF16: 3.2466419 | AG16: 65.281448 | AH16: 3682 | AI16: 0.023984869 | AJ16: 0.22601513 | AK16: 0.25 | AL16: 9.5129376e-13 | AM16: 2722000000000 | AO16: =C16*O16 -> 224056853128933 | AP16: =V16*AH16 -> 1.3315144e+18 | AQ16: =AP16+AO16 -> 1.3317384e+18 | AR16: =B16*E16*N16+B16*D16*M16 -> 4.2588162e+11 | AS16: =U16*X16*AG16+U16*W16*AF16 -> 2.7240335e+14 | AT16: =AS16+AR16 -> 2.7282924e+14 | AU16: =B16*F16*$AP$5+B16*G16*$AP$5 -> 8.0699256e+11 | AV16: =U16*Y16*$AP$5+U16*Z16*$AP$5 -> 1.2568401e+13 | AW16: =AV16+AU16 -> 1.3375394e+13
A17: regions | B17: dens_fw_species_C | C17: dens_fw_species_RoW | D17: dens_marine_species_C | E17: dens_marine_species_RoW | F17: dens_ter_species_C | G17: dens_ter_species_RoW
A18: North America | B18: 0.075 | C18: 0.925 | D18: 0.2332 | E18: 0.7668 | F18: 0.0324 | G18: 0.9676
A19: Latin America | B19: 0.2989 | C19: 0.7011 | D19: 0.2657 | E19: 0.7343 | F19: 0.3433 | G19: 0.6567
A20: Europe | B20: 0.1022 | C20: 0.8978 | D20: 0.0402 | E20: 0.9598 | F20: 0.0831 | G20: 0.9169
A21: Africa & Middle East | B21: 0.2268 | C21: 0.7732 | D21: 0.2293 | E21: 0.7707 | F21: 0.2283 | G21: 0.7717
A22: Central Asia | B22: 0.1225 | C22: 0.8775 | D22: 0.2538 | E22: 0.7462 | F22: 0.076 | G22: 0.924
A23: Southeast Asia | B23: 0.288 | C23: 0.712 | D23: 0.3822 | E23: 0.6178 | F23: 0.2298 | G23: 0.7702
A24: Northern regions | B24: 0.057 | C24: 0.943 | D24: 0.2129 | E24: 0.7871 | F24: 0.0214 | G24: 0.9786
A25: Oceania | B25: 0.0892 | C25: 0.9108 | D25: 0.1637 | E25: 0.8363 | F25: 0.131 | G25: 0.869

Sheet 4.1.Regio_param
B2: Regionalization parameters
B4: Python Input (Louvet et al., 2026) | C4: SB4P input in R
A5: regions | B5: parameter | C5: Variable | D5: Scale | E5: SubCompart | F5: North America | G5: Latin America | H5: Europe | I5: Africa & Middle East | J5: Central Asia | K5: Southeast Asia | L5: Northern regions | M5: Oceania | N5: description | O5: unit | P5: source | Q5: SB4P notes
A6: CONTINENTAL SCALE | B6: area_land_C | D6: Regional | F6: 1.448998e+13 | G6: 2.08779e+13 | H6: 8.5662136e+12 | I6: 3.429833e+13 | J6: 1.6876936e+13 | K6: 1.6866064e+13 | L6: 1.8299925e+13 | M6: 8.1247481e+12 | N6: area of land | O6: [m2] | P6: USEtox
B7: area_sea_C | D7: Regional | F7: 1.8374074e+12 | G7: 2.9728967e+12 | H7: 1.7001869e+12 | I7: 1.5904011e+12 | J7: 7.3629569e+11 | K7: 5.3374046e+12 | L7: 5.6248619e+12 | M7: 2.2405685e+12 | N7: area of sea | O7: [m2] | P7: USEtox
C8: TotalArea | D8: Regional | F8: =F6+F7 -> 1.6327387e+13 | G8: =G6+G7 -> 2.3850797e+13 | H8: =H6+H7 -> 1.02664e+13 | I8: =I6+I7 -> 3.5888731e+13 | J8: =J6+J7 -> 1.7613232e+13 | K8: =K6+K7 -> 2.2203468e+13 | L8: =L6+L7 -> 2.3924787e+13 | M8: =M6+M7 -> 1.0365317e+13
C9: FRACsea | D9: Regional | F9: =F7/F8 -> 0.1125353 | G9: =G7/G8 -> 0.12464559 | H9: =H7/H8 -> 0.16560691 | I9: =I7/I8 -> 0.044314777 | J9: =J7/J8 -> 0.041803555 | K9: =K7/K8 -> 0.24038608 | L9: =L7/L8 -> 0.23510604 | M9: =M7/M8 -> 0.21616016
B10: areafrac_rw_C | C10: landFRAC | D10: Regional | E10: river | F10: 0.0034304356 | G10: 0.0064487285 | H10: 0.0050055029 | I10: 0.00013076169 | J10: 0.0022461359 | K10: 0.012328111 | L10: 0.0046867292 | M10: 0.0008998234 | N10: fraction of land area allocated to river | O10: - | P10: Calculated with HydroATLAS
B11: areafrac_lw_C | C11: landFRAC | D11: Regional | E11: lake | F11: 0.083169844 | G11: 0.012684412 | H11: 0.025460718 | I11: 0.013897746 | J11: 0.027333048 | K11: 0.026854951 | L11: 0.051861908 | M11: 0.0058477675 | N11: fraction of land area allocated to lake | O11: - | P11: Calculated with HydroATLAS
B12: areafrac_nat_soil_C | C12: landFRAC | D12: Regional | E12: naturalsoil | F12: 0.63128839 | G12: 0.65377256 | H12: 0.584526 | I12: 0.58847302 | J12: 0.5213891 | K12: 0.49742035 | L12: 0.82125082 | M12: 0.53527812 | N12: fraction of land area allocated to natural soil | O12: - | P12: USEtox
B13: areafrac_agr_soil_C | C13: landFRAC | D13: Regional | E13: agriculturalsoil | F13: 0.28211133 | G13: 0.3270943 | H13: 0.38500778 | I13: 0.39749848 | J13: 0.44903172 | K13: 0.46339659 | L13: 0.12220054 | M13: 0.45797429 | N13: fraction of land area allocated to agricultural soil | O13: - | P13: USEtox
B14: areafrac_agr_soil_C | C14: landFRAC | D14: Regional | E14: othersoil | F14: 1e-20 | G14: 1e-20 | H14: 1e-20 | I14: 1e-20 | J14: 1e-20 | K14: 1e-20 | L14: 1e-20 | M14: 1e-20 | N14: fraction of land area allocated to other soil | O14: - | P14: - | Q14: Set to 0 to get rid of it
B15: fracsf_rw_C | D15: Regional | F15: 0.039612292 | G15: 0.33704496 | H15: 0.16429681 | I15: 0.0093211403 | J15: 0.075936371 | K15: 0.31462858 | L15: 0.082879614 | M15: 0.13335477 | N15: fraction of surface water allocated to river | O15: - | P15: Calculated with HydroATLAS
B16: fracsf_lw_C | D16: Regional | F16: 0.96038771 | G16: 0.66295504 | H16: 0.83570319 | I16: 0.99067886 | J16: 0.92406363 | K16: 0.68537142 | L16: 0.91712039 | M16: 0.86664523 | N16: fraction of surface water allocated to lake | O16: - | P16: Calculated with HydroATLAS
B17: temp_C | C17: Temp | D17: Regional | F17: 285.15 | G17: 285.15 | H17: 285.15 | I17: 285.15 | J17: 285.15 | K17: 285.15 | L17: 285.15 | M17: 285.15 | N17: temperature | O17: K | P17: USEtox
B18: wind_speed_C | C18: WINDspeed | D18: Regional | F18: 3 | G18: 3 | H18: 3 | I18: 3 | J18: 3 | K18: 3 | L18: 3 | M18: 3 | N18: wind speed | O18: [m*s-1] | P18: USEtox
B19: rain_rate_C | D19: Regional | F19: 2.2427398e-08 | G19: 5.1120312e-08 | H19: 1.7523958e-08 | I19: 2.0870339e-08 | J19: 6.9029435e-09 | K19: 4.8075939e-08 | L19: 1.5527965e-08 | M19: 4.1085817e-08 | N19: rain rate | O19: [m*s-1] | P19: USEtox
C20: RAINrate | D20: Regional | F20: =F19*1000*365*24*3600 -> 707.27042 | G20: =G19*1000*365*24*3600 -> 1612.1301 | H20: =H19*1000*365*24*3600 -> 552.63553 | I20: =I19*1000*365*24*3600 -> 658.16701 | J20: =J19*1000*365*24*3600 -> 217.69123 | K20: =K19*1000*365*24*3600 -> 1516.1228 | L20: =L19*1000*365*24*3600 -> 489.68992 | M20: =M19*1000*365*24*3600 -> 1295.6823 | N20: rain rate | O20: [mm*yr-1] | P20: USEtox
B21: depth_rw_C | C21: VertDistance | D21: Regional | E21: river | F21: 2.3696042 | G21: 4.3917246 | H21: 1.9467369 | I21: 2.4790569 | J21: 2.2211414 | K21: 3.3070096 | L21: 2.9280377 | M21: 1.0055754 | N21: depth river water | O21: [m] | P21: Calculated with HydroATLAS
B22: depth_lw_C | C22: VertDistance | D22: Regional | E22: lake | F22: 29.533 | G22: 25.706 | H22: 26.89 | I22: 115.865 | J22: 33.135 | K22: 17.388 | L22: 131.869 | M22: 8.809 | N22: depth lake water | O22: [m] | P22: Calculated with HydroATLAS
B23: depth_sw_C | C23: VertDistance | D23: Regional | E23: sea | F23: 10 | G23: 10 | H23: 10 | I23: 10 | J23: 10 | K23: 10 | L23: 10 | M23: 10 | N23: depth sea water | O23: [m] | P23: USEtox
C24: VertDistance | D24: Regional | E24: deepocean | F24: 90 | G24: 90 | H24: 90 | I24: 90 | J24: 90 | K24: 90 | L24: 90 | M24: 90 | N24: depth water column | P24: Hajjar et al.
B25: frac_runoff_rw_C | D25: Regional | F25: 0.014496812 | G25: 0.12852081 | H25: 0.028291286 | I25: 0.0017166348 | J25: 0.035221577 | K25: 0.082847468 | L25: 0.029771738 | M25: 0.025343262 | N25: fraction runoff to river | O25: - | P25: Fraction runoff in USEtox * Fraction of surface water allocated to river
B26: frac_runoff_lw_C | D26: Regional | F26: 0.3514707 | G26: 0.25279571 | H26: 0.14390491 | I26: 0.18244911 | J26: 0.42860856 | K26: 0.18047085 | L26: 0.32944492 | M26: 0.16470065 | N26: fraction runoff to lake | O26: - | P26: Fraction runoff in USEtox * Fraction of surface water allocated to lake
C27: FRACrun | D27: Regional | F27: 0.36596752 | G27: 0.38131652 | H27: 0.1721962 | I27: 0.18416575 | J27: 0.46383013 | K27: 0.26331831 | L27: 0.35921666 | M27: 0.19004392 | N27: fraction runoff | O27: - | P27: USEtox
B28: frac_infiltr_C | C28: FRACinf | D28: Regional | F28: 0.26947836 | G28: 0.26947836 | H28: 0.26947836 | I28: 0.26947836 | J28: 0.26947836 | K28: 0.26947836 | L28: 0.26947836 | M28: 0.26947836 | N28: fraction infiltration | O28: - | P28: USEtox
B29: soil_ero_C | D29: Regional | F29: 9.5129376e-13 | G29: 9.5129376e-13 | H29: 9.5129376e-13 | I29: 9.5129376e-13 | J29: 9.5129376e-13 | K29: 9.5129376e-13 | L29: 9.5129376e-13 | M29: 9.5129376e-13 | N29: soil erosion | O29: [m*s-1] | P29: USEtox | Q29: Not changed - same value
B30: irrig_C | D30: Regional | F30: 1.9675113e+11 | G30: 232770200000 | H30: 1.154305e+11 | I30: 272246800000 | J30: 2.2477736e+11 | K30: 1.6684885e+12 | L30: 9.689203e+08 | M30: 1.0566e+10 | N30: irrigation | O30: [m3] | P30: USEtox
B31: dens_fw_species_C | C31: dens_fw_species_C | F31: 0.075 | G31: 0.2989 | H31: 0.1022 | I31: 0.2268 | J31: 0.1225 | K31: 0.288 | L31: 0.057 | M31: 0.0892 | P31: Louvet et al. (2025)
B32: dens_marine_species_C | C32: dens_marine_species_C | F32: 0.087273953 | G32: 0.16039537 | H32: 0.009041896 | I32: 0.096315849 | J32: 0.075367854 | K32: 0.27636752 | L32: 0.031955521 | M32: 0.13029316 | P32: Louvet et al. (2025)
B33: dens_ter_species_C | C33: dens_ter_species_C | F33: 0.0324 | G33: 0.3433 | H33: 0.0831 | I33: 0.2283 | J33: 0.076 | K33: 0.2298 | L33: 0.0214 | M33: 0.131 | P33: Louvet et al. (2025)
C34: UVintensity | D34: Regional | E34: agriculturalsoil | F34: {=_xlfn.XLOOKUP($E34, UVintensity!$L$3:$L$14, _xlfn.XLOOKUP(F$5, UVintensity!$M$2:$U$2, UVintensity!$M$3:$U$14))} -> 0 | G34: {=_xlfn.XLOOKUP($E34, UVintensity!$L$3:$L$14, _xlfn.XLOOKUP(G$5, UVintensity!$M$2:$U$2, UVintensity!$M$3:$U$14))} -> 0 | H34: {=_xlfn.XLOOKUP($E34, UVintensity!$L$3:$L$14, _xlfn.XLOOKUP(H$5, UVintensity!$M$2:$U$2, UVintensity!$M$3:$U$14))} -> 0 | I34: {=_xlfn.XLOOKUP($E34, UVintensity!$L$3:$L$14, _xlfn.XLOOKUP(I$5, UVintensity!$M$2:$U$2, UVintensity!$M$3:$U$14))} -> 0 | J34: {=_xlfn.XLOOKUP($E34, UVintensity!$L$3:$L$14, _xlfn.XLOOKUP(J$5, UVintensity!$M$2:$U$2, UVintensity!$M$3:$U$14))} -> 0 | K34: {=_xlfn.XLOOKUP($E34, UVintensity!$L$3:$L$14, _xlfn.XLOOKUP(K$5, UVintensity!$M$2:$U$2, UVintensity!$M$3:$U$14))} -> 0 | L34: {=_xlfn.XLOOKUP($E34, UVintensity!$L$3:$L$14, _xlfn.XLOOKUP(L$5, UVintensity!$M$2:$U$2, UVintensity!$M$3:$U$14))} -> 0 | M34: {=_xlfn.XLOOKUP($E34, UVintensity!$L$3:$L$14, _xlfn.XLOOKUP(M$5, UVintensity!$M$2:$U$2, UVintensity!$M$3:$U$14))} -> 0 | O34: [W*m-2] | P34: PlasticFADE model | T34: 0.087273953
C35: UVintensity | D35: Regional | E35: air | F35: {=_xlfn.XLOOKUP($E35, UVintensity!$L$3:$L$14, _xlfn.XLOOKUP(F$5, UVintensity!$M$2:$U$2, UVintensity!$M$3:$U$14))} -> 8.02 | G35: {=_xlfn.XLOOKUP($E35, UVintensity!$L$3:$L$14, _xlfn.XLOOKUP(G$5, UVintensity!$M$2:$U$2, UVintensity!$M$3:$U$14))} -> 11.78 | H35: {=_xlfn.XLOOKUP($E35, UVintensity!$L$3:$L$14, _xlfn.XLOOKUP(H$5, UVintensity!$M$2:$U$2, UVintensity!$M$3:$U$14))} -> 5.23 | I35: {=_xlfn.XLOOKUP($E35, UVintensity!$L$3:$L$14, _xlfn.XLOOKUP(I$5, UVintensity!$M$2:$U$2, UVintensity!$M$3:$U$14))} -> 13.82 | J35: {=_xlfn.XLOOKUP($E35, UVintensity!$L$3:$L$14, _xlfn.XLOOKUP(J$5, UVintensity!$M$2:$U$2, UVintensity!$M$3:$U$14))} -> 5.63 | K35: {=_xlfn.XLOOKUP($E35, UVintensity!$L$3:$L$14, _xlfn.XLOOKUP(K$5, UVintensity!$M$2:$U$2, UVintensity!$M$3:$U$14))} -> 13.65 | L35: {=_xlfn.XLOOKUP($E35, UVintensity!$L$3:$L$14, _xlfn.XLOOKUP(L$5, UVintensity!$M$2:$U$2, UVintensity!$M$3:$U$14))} -> 3.64 | M35: {=_xlfn.XLOOKUP($E35, UVintensity!$L$3:$L$14, _xlfn.XLOOKUP(M$5, UVintensity!$M$2:$U$2, UVintensity!$M$3:$U$14))} -> 11.85 | O35: [W*m-2] | P35: PlasticFADE model | T35: 0.16039537
C36: UVintensity | D36: Regional | E36: cloudwater | F36: {=_xlfn.XLOOKUP($E36, UVintensity!$L$3:$L$14, _xlfn.XLOOKUP(F$5, UVintensity!$M$2:$U$2, UVintensity!$M$3:$U$14))} -> 8.02 | G36: {=_xlfn.XLOOKUP($E36, UVintensity!$L$3:$L$14, _xlfn.XLOOKUP(G$5, UVintensity!$M$2:$U$2, UVintensity!$M$3:$U$14))} -> 11.78 | H36: {=_xlfn.XLOOKUP($E36, UVintensity!$L$3:$L$14, _xlfn.XLOOKUP(H$5, UVintensity!$M$2:$U$2, UVintensity!$M$3:$U$14))} -> 5.23 | I36: {=_xlfn.XLOOKUP($E36, UVintensity!$L$3:$L$14, _xlfn.XLOOKUP(I$5, UVintensity!$M$2:$U$2, UVintensity!$M$3:$U$14))} -> 13.82 | J36: {=_xlfn.XLOOKUP($E36, UVintensity!$L$3:$L$14, _xlfn.XLOOKUP(J$5, UVintensity!$M$2:$U$2, UVintensity!$M$3:$U$14))} -> 5.63 | K36: {=_xlfn.XLOOKUP($E36, UVintensity!$L$3:$L$14, _xlfn.XLOOKUP(K$5, UVintensity!$M$2:$U$2, UVintensity!$M$3:$U$14))} -> 13.65 | L36: {=_xlfn.XLOOKUP($E36, UVintensity!$L$3:$L$14, _xlfn.XLOOKUP(L$5, UVintensity!$M$2:$U$2, UVintensity!$M$3:$U$14))} -> 3.64 | M36: {=_xlfn.XLOOKUP($E36, UVintensity!$L$3:$L$14, _xlfn.XLOOKUP(M$5, UVintensity!$M$2:$U$2, UVintensity!$M$3:$U$14))} -> 11.85 | O36: [W*m-2] | P36: PlasticFADE model | T36: 0.009041896
C37: UVintensity | D37: Regional | E37: freshwatersediment | F37: {=_xlfn.XLOOKUP($E37, UVintensity!$L$3:$L$14, _xlfn.XLOOKUP(F$5, UVintensity!$M$2:$U$2, UVintensity!$M$3:$U$14))} -> 0 | G37: {=_xlfn.XLOOKUP($E37, UVintensity!$L$3:$L$14, _xlfn.XLOOKUP(G$5, UVintensity!$M$2:$U$2, UVintensity!$M$3:$U$14))} -> 0 | H37: {=_xlfn.XLOOKUP($E37, UVintensity!$L$3:$L$14, _xlfn.XLOOKUP(H$5, UVintensity!$M$2:$U$2, UVintensity!$M$3:$U$14))} -> 0 | I37: {=_xlfn.XLOOKUP($E37, UVintensity!$L$3:$L$14, _xlfn.XLOOKUP(I$5, UVintensity!$M$2:$U$2, UVintensity!$M$3:$U$14))} -> 0 | J37: {=_xlfn.XLOOKUP($E37, UVintensity!$L$3:$L$14, _xlfn.XLOOKUP(J$5, UVintensity!$M$2:$U$2, UVintensity!$M$3:$U$14))} -> 0 | K37: {=_xlfn.XLOOKUP($E37, UVintensity!$L$3:$L$14, _xlfn.XLOOKUP(K$5, UVintensity!$M$2:$U$2, UVintensity!$M$3:$U$14))} -> 0 | L37: {=_xlfn.XLOOKUP($E37, UVintensity!$L$3:$L$14, _xlfn.XLOOKUP(L$5, UVintensity!$M$2:$U$2, UVintensity!$M$3:$U$14))} -> 0 | M37: {=_xlfn.XLOOKUP($E37, UVintensity!$L$3:$L$14, _xlfn.XLOOKUP(M$5, UVintensity!$M$2:$U$2, UVintensity!$M$3:$U$14))} -> 0 | O37: [W*m-2] | P37: PlasticFADE model | T37: 0.096315849
C38: UVintensity | D38: Regional | E38: lake | F38: {=_xlfn.XLOOKUP($E38, UVintensity!$L$3:$L$14, _xlfn.XLOOKUP(F$5, UVintensity!$M$2:$U$2, UVintensity!$M$3:$U$14))} -> 0.067966102 | G38: {=_xlfn.XLOOKUP($E38, UVintensity!$L$3:$L$14, _xlfn.XLOOKUP(G$5, UVintensity!$M$2:$U$2, UVintensity!$M$3:$U$14))} -> 0.11459144 | H38: {=_xlfn.XLOOKUP($E38, UVintensity!$L$3:$L$14, _xlfn.XLOOKUP(H$5, UVintensity!$M$2:$U$2, UVintensity!$M$3:$U$14))} -> 0.048605948 | I38: {=_xlfn.XLOOKUP($E38, UVintensity!$L$3:$L$14, _xlfn.XLOOKUP(I$5, UVintensity!$M$2:$U$2, UVintensity!$M$3:$U$14))} -> 0.029810181 | J38: {=_xlfn.XLOOKUP($E38, UVintensity!$L$3:$L$14, _xlfn.XLOOKUP(J$5, UVintensity!$M$2:$U$2, UVintensity!$M$3:$U$14))} -> 0.042522659 | K38: {=_xlfn.XLOOKUP($E38, UVintensity!$L$3:$L$14, _xlfn.XLOOKUP(K$5, UVintensity!$M$2:$U$2, UVintensity!$M$3:$U$14))} -> 0.19612069 | L38: {=_xlfn.XLOOKUP($E38, UVintensity!$L$3:$L$14, _xlfn.XLOOKUP(L$5, UVintensity!$M$2:$U$2, UVintensity!$M$3:$U$14))} -> 0.006899166 | M38: {=_xlfn.XLOOKUP($E38, UVintensity!$L$3:$L$14, _xlfn.XLOOKUP(M$5, UVintensity!$M$2:$U$2, UVintensity!$M$3:$U$14))} -> 0.33664773 | O38: [W*m-2] | P38: PlasticFADE model | T38: 0.075367854
C39: UVintensity | D39: Regional | E39: lakesediment | F39: {=_xlfn.XLOOKUP($E39, UVintensity!$L$3:$L$14, _xlfn.XLOOKUP(F$5, UVintensity!$M$2:$U$2, UVintensity!$M$3:$U$14))} -> 0 | G39: {=_xlfn.XLOOKUP($E39, UVintensity!$L$3:$L$14, _xlfn.XLOOKUP(G$5, UVintensity!$M$2:$U$2, UVintensity!$M$3:$U$14))} -> 0 | H39: {=_xlfn.XLOOKUP($E39, UVintensity!$L$3:$L$14, _xlfn.XLOOKUP(H$5, UVintensity!$M$2:$U$2, UVintensity!$M$3:$U$14))} -> 0 | I39: {=_xlfn.XLOOKUP($E39, UVintensity!$L$3:$L$14, _xlfn.XLOOKUP(I$5, UVintensity!$M$2:$U$2, UVintensity!$M$3:$U$14))} -> 0 | J39: {=_xlfn.XLOOKUP($E39, UVintensity!$L$3:$L$14, _xlfn.XLOOKUP(J$5, UVintensity!$M$2:$U$2, UVintensity!$M$3:$U$14))} -> 0 | K39: {=_xlfn.XLOOKUP($E39, UVintensity!$L$3:$L$14, _xlfn.XLOOKUP(K$5, UVintensity!$M$2:$U$2, UVintensity!$M$3:$U$14))} -> 0 | L39: {=_xlfn.XLOOKUP($E39, UVintensity!$L$3:$L$14, _xlfn.XLOOKUP(L$5, UVintensity!$M$2:$U$2, UVintensity!$M$3:$U$14))} -> 0 | M39: {=_xlfn.XLOOKUP($E39, UVintensity!$L$3:$L$14, _xlfn.XLOOKUP(M$5, UVintensity!$M$2:$U$2, UVintensity!$M$3:$U$14))} -> 0 | O39: [W*m-2] | P39: PlasticFADE model | T39: 0.27636752
C40: UVintensity | D40: Regional | E40: marinesediment | F40: {=_xlfn.XLOOKUP($E40, UVintensity!$L$3:$L$14, _xlfn.XLOOKUP(F$5, UVintensity!$M$2:$U$2, UVintensity!$M$3:$U$14))} -> 0 | G40: {=_xlfn.XLOOKUP($E40, UVintensity!$L$3:$L$14, _xlfn.XLOOKUP(G$5, UVintensity!$M$2:$U$2, UVintensity!$M$3:$U$14))} -> 0 | H40: {=_xlfn.XLOOKUP($E40, UVintensity!$L$3:$L$14, _xlfn.XLOOKUP(H$5, UVintensity!$M$2:$U$2, UVintensity!$M$3:$U$14))} -> 0 | I40: {=_xlfn.XLOOKUP($E40, UVintensity!$L$3:$L$14, _xlfn.XLOOKUP(I$5, UVintensity!$M$2:$U$2, UVintensity!$M$3:$U$14))} -> 0 | J40: {=_xlfn.XLOOKUP($E40, UVintensity!$L$3:$L$14, _xlfn.XLOOKUP(J$5, UVintensity!$M$2:$U$2, UVintensity!$M$3:$U$14))} -> 0 | K40: {=_xlfn.XLOOKUP($E40, UVintensity!$L$3:$L$14, _xlfn.XLOOKUP(K$5, UVintensity!$M$2:$U$2, UVintensity!$M$3:$U$14))} -> 0 | L40: {=_xlfn.XLOOKUP($E40, UVintensity!$L$3:$L$14, _xlfn.XLOOKUP(L$5, UVintensity!$M$2:$U$2, UVintensity!$M$3:$U$14))} -> 0 | M40: {=_xlfn.XLOOKUP($E40, UVintensity!$L$3:$L$14, _xlfn.XLOOKUP(M$5, UVintensity!$M$2:$U$2, UVintensity!$M$3:$U$14))} -> 0 | O40: [W*m-2] | P40: PlasticFADE model | T40: 0.031955521
